Workbook

Sheet Start Here
A1: Backend + AI Engineer Marathon v4: Daily Planner
A2: Wed 04 Nov 2026 to Sun 30 May 2027 | 30 weeks | ~25 h/week | companion: Marathon_Roadmap_v4.docx
A5: How to use (60 seconds)
A6: 1. Open 'Today' | B6: It shows today's card, the steps, the DONE WHEN goal, the LARP topic and the WIN rule. That is all you need for the day.
A7: 2. Work the card | B7: 22:00-23:45: project card (Read 10 / Build 70 / Verify 15 / Commit + log 10). 23:45-01:00: LARP slot with the tutor prompt (sheet 'Tutor Prompts') + the questions in 'LARP Bank'.
A8: 3. Tick it | B8: 'Daily Plan' column A (☐ -> ☑) when the WIN rule is met. Column R for your DSA problem in office. Rows turn green; today's row is highlighted.
A9: 4. Sunday review | B9: Weekly Plan shows % done per week. Missed more than 2 cards? Move dates, don't cram (rules in the roadmap).
A10: 5. Yellow cells are yours | B10: Notes, Job Tracker, Interview Log, Story Bank, Design Choices answers, scores. Rows marked EXAMPLE show the format.
A12: Your week
A13: Mon-Thu | B13: 22:00-23:45 PROJECT | 23:45-01:00 LARP (teach 25, quiz 20, interview + scenarios 25, flashcards 5)
A14: Fri | B14: 22:00-23:45 BUFFER (carry-over, else polish + applications) | 23:45-01:00 WEEKLY MOCK interview
A15: Sat (5 h + 1 optional) | B15: 10:30-13:30 PROJECT | 14:30-15:30 BACKEND LAB | 16:00-17:00 JOB HUNT | 17:00-18:00 optional buffer
A16: Sun (5 h) | B16: 10:30-13:00 PROJECT | 14:00-15:00 MOCK & STORY | 15:00-16:00 READ / CERT (AI-102) | 16:00-16:30 WEEKLY REVIEW
A17: DSA | B17: Not scheduled here: you do it in office. Tick column R.
A19: Gates
A20: Gate 0 | B20: Sun 22 Nov 2026: Resume v1, LinkedIn, GitHub ready (DocuLens with hybrid search and first eval table). First 3 applications; 8/week next week. Interviews are practice and market information.
A21: Gate 1 | B21: Sun 06 Dec 2026: DocuLens v1 deployed on Azure with eval report and demo. Resume v2. 10-15 applications/week + 5 referral asks.
A22: DocuLens v1.5 | B22: Sun 13 Dec 2026: Workflow automation released: claim intake, review queue, webhooks, text-to-SQL, workflow eval. Resume bullets updated.
A23: Gate 2 | B23: Sun 17 Jan 2027: AI SRE Copilot v1 finished. Resume v3 with two projects. Aim at AI-agent / LLM-engineer roles.
A24: PDF Translator v1.0 | B24: Sun 14 Feb 2027: Your PRD built (phases 1-8) + shared AI gateway. Resume v4 with three projects.
A25: AI-102 exam | B25: Sat 20 Feb 2027: Azure AI Engineer Associate (company-paid). Check the current exam code on Microsoft Learn before booking.
A26: Offer rule | B26: Take the first offer that clears your pay bar AND has real engineering substance. Then drop to maintenance mode (roadmap section 9).
A28: Rules that keep it alive
A29: Minimum viable day | B29: Exhausted? 25 minutes of the card's first step + 15 minutes of LARP questions aloud. Tick nothing, but keep the streak in Notes.
A30: One card, one session | B30: Never pull tomorrow's card forward. If unfinished: clean commit + one carry-over line; Friday absorbs it.
A31: Stop at 01:00 | B31: You wake at 8:30. Sleep is part of the plan.
A32: Explain every line | B32: Use Claude Code/Copilot freely, but end each session with 'quiz me on today's code'.
A33: Never edit eval labels | B33: Fix prompts and tools, never the golden answers. That is what makes your numbers quotable.
A35: Progress
A36: Days ticked | B36: =COUNTIF('Daily Plan'!$A$2:$A$209,"☑")&" of "&COUNTA('Daily Plan'!$B$2:$B$209)
A37: Project cards done | B37: =COUNTIFS('Daily Plan'!$A$2:$A$209,"☑",'Daily Plan'!$H$2:$H$209,"<>BUF",'Daily Plan'!$H$2:$H$209,"<>")
A38: DSA days (office) | B38: =COUNTIF('Daily Plan'!$R$2:$R$209,"☑")
A39: Applications logged | B39: =COUNTA('Job Tracker'!$A$7:$A$400)
A40: Interview questions logged | B40: =COUNTA('Interview Log'!$D$7:$D$400)

Sheet Today
A1: Today
A2: Opens on today's date. Type any date in B3 (yellow) to preview that day; clear it to go back to today.
A3: Preview date (optional)
A4: Showing | B4: =IF(ISNUMBER(B3),B3,MIN(MAX(TODAY(),'Daily Plan'!$B$2),'Daily Plan'!$B$209))
A5: Plan row | B5: =IFERROR(MATCH(B4,'Daily Plan'!$B$2:$B$209,0),"")
A6: Week | B6: =IF($B$5="","",INDEX('Daily Plan'!$D$2:$D$209,$B$5)&"")
A7: Stage | B7: =IF($B$5="","",INDEX('Daily Plan'!$E$2:$E$209,$B$5)&"")
A8: Slot 1 | B8: =IF($B$5="","",INDEX('Daily Plan'!$G$2:$G$209,$B$5)&"")
A9: Card | B9: =IF($B$5="","",INDEX('Daily Plan'!$H$2:$H$209,$B$5)&"")
A10: Task | B10: =IF($B$5="","",INDEX('Daily Plan'!$I$2:$I$209,$B$5)&"")
A11: How (steps) | B11: =IF($B$5="","",INDEX('Daily Plan'!$J$2:$J$209,$B$5)&"")
A12: DONE WHEN (end goal) | B12: =IF($B$5="","",INDEX('Daily Plan'!$K$2:$K$209,$B$5)&"")
A13: Learn first | B13: =IF($B$5="","",INDEX('Daily Plan'!$L$2:$L$209,$B$5)&"")
A14: Slot 2 | B14: =IF($B$5="","",INDEX('Daily Plan'!$M$2:$M$209,$B$5)&"")
A15: LARP / mock | B15: =IF($B$5="","",INDEX('Daily Plan'!$N$2:$N$209,$B$5)&"")
A16: Extra blocks | B16: =IF($B$5="","",INDEX('Daily Plan'!$O$2:$O$209,$B$5)&"")
A17: Day is a WIN when | B17: =IF($B$5="","",INDEX('Daily Plan'!$P$2:$P$209,$B$5)&"")
A18: Milestone | B18: =IF($B$5="","",INDEX('Daily Plan'!$S$2:$S$209,$B$5)&"")
A20: Tomorrow | B20: =IF($B$5="","",IFERROR(INDEX('Daily Plan'!$H$2:$H$209,$B$5+1)&" "&INDEX('Daily Plan'!$I$2:$I$209,$B$5+1),""))
A21: Progress | B21: =COUNTIF('Daily Plan'!$A$2:$A$209,"☑")&" of "&COUNTA('Daily Plan'!$B$2:$B$209)&" days ticked; "&COUNTIF('Daily Plan'!$R$2:$R$209,"☑")&" DSA days"

Sheet Daily Plan
A1: Done | B1: Date | C1: Day | D1: Wk | E1: Stage | F1: Hrs | G1: Slot 1 | H1: Card | I1: Task | J1: How (steps) | K1: Done when = end goal of the day | L1: Learn first | M1: Slot 2 | N1: LARP / mock | O1: Weekend + Friday extra blocks | P1: Day is a WIN when | Q1: Apply quota (week) | R1: DSA @ office | S1: Milestone / gate | T1: Notes / carry-over
A2: ☐ | B2: 46330 | C2: Wed | D2: 1 | E2: 1: DocuLens | F2: 3 | G2: 22:00-23:45 PROJECT (105 min) | H2: D01 | I2: Dev setup + repo + hello FastAPI | J2: 1. Install WSL2 (Ubuntu), Docker Desktop with WSL integration, VS Code + WSL extension, git, uv. Work inside WSL from now on (Celery, Tesseract and k8s tooling behave better there). 2. uv init doculens; add fastapi, uvicorn[standard], pydantic-settings; dev deps: pytest, pytest-asyncio, httpx, ruff, mypy, pre-commit. 3. Layout: app/main.py (app factory), app/api/routes/health.py, app/core/config.py, tests/, docs/decisions/, docs/LOG.md. 4. GET /health returns {"status":"ok","version":...}. Write one test with httpx.AsyncClient + ASGITransport. 5. Makefile (run from WSL): make dev, make test, make lint. Add pre-commit with ruff + ruff-format. 6. Create GitHub repo, push, write a 5-line README (what it will be). Stretch: Add a GitHub Actions workflow that runs `make lint test` (you will formalise CI in D25). | K2: `make test` is green, `make lint` is clean, repo is on GitHub, and `docker run hello-world` works inside WSL. | L2: uv docs (docs.astral.sh/uv) 'Projects' page; FastAPI tutorial 'First Steps' and 'Testing' (fastapi.tiangolo.com); WSL2 + Docker Desktop install guide (learn.microsoft.com/windows/wsl). | M2: 23:45-01:00 LARP (75 min) | N2: L01 Python async/await and the event loop | P2: WIN = project 'Done when' met and pushed (or one clean carry-over line in docs/LOG.md) + LARP quiz scored, misses written as flashcards + DSA ticked (office). | R2: ☐ | S2: Marathon starts tonight at 22:00 with D01.
A3: ☐ | B3: 46331 | C3: Thu | D3: 1 | E3: 1: DocuLens | F3: 3 | G3: 22:00-23:45 PROJECT (105 min) | H3: D02 | I3: Docker Compose: Postgres + pgvector + Redis, settings, readiness | J3: 1. docker-compose.yml: pgvector/pgvector:pg16 (volume, healthcheck pg_isready) and redis:7 (healthcheck redis-cli ping). 2. app/core/config.py: Settings(BaseSettings) with DATABASE_URL, REDIS_URL, ENV; .env.example committed, .env ignored. 3. app/db/session.py: async engine (asyncpg) + async_sessionmaker; FastAPI dependency get_session(). 4. GET /health/ready: runs SELECT 1 and Redis PING concurrently with asyncio.gather and a 1 s timeout each; returns per-dependency status and 503 if any fails. 5. Test: ready endpoint returns 200 with compose up; unit test with a failing fake returns 503. Stretch: Write docs/decisions/0001-one-database.md: why Postgres+pgvector instead of a separate vector DB for v1. | K3: `docker compose up -d` then `curl /health/ready` returns {"db":"ok","redis":"ok"}; stopping Redis makes it return 503. | L3: pgvector README (github.com/pgvector/pgvector) 'Docker' + 'Getting started'; SQLAlchemy 2.0 'Asynchronous I/O' page; pydantic-settings docs. | M3: 23:45-01:00 LARP (75 min) | N3: L02 FastAPI internals: dependency injection, Pydantic v2, sync vs async | P3: WIN = project 'Done when' met and pushed (or one clean carry-over line in docs/LOG.md) + LARP quiz scored, misses written as flashcards + DSA ticked (office). | R3: ☐
A4: ☐ | B4: 46332 | C4: Fri | D4: 1 | E4: 1: DocuLens | F4: 3 | G4: 22:00-23:45 PROJECT (105 min) | H4: D03 | I4: Alembic + data model v1 | J4: 1. alembic init -t async migrations; point env.py at your Base metadata and settings. 2. Models: documents(id uuid pk, workspace_id uuid null, filename, sha256 unique-per-workspace, status, page_count, metadata jsonb, created_at). 3. chunks(id uuid, document_id fk, page int, bbox jsonb, section text, text text, token_count int, content_hash text, embedding vector(384), metadata jsonb). 4. First migration runs CREATE EXTENSION IF NOT EXISTS vector; autogenerate the rest and READ the generated file before applying. 5. Test: upgrade head on an empty DB, insert one document + chunk, downgrade base. | K4: `alembic upgrade head` and `alembic downgrade base` both succeed on a clean database and the round-trip test passes. | L4: Alembic tutorial (alembic.sqlalchemy.org) 'Auto Generating Migrations'; pgvector 'Storing' section. | M4: 23:45-01:00 WEEKLY MOCK | N4: Weekly mock interview (Friday prompt). Topics: L01 Python async/await and the event loop, L02 FastAPI internals: dependency injection, Pydantic v2, sync vs async | P4: WIN = carry-over cleared (or the polish task done) + weekly mock scored with your 5 'rewrite' answers listed. | R4: ☐
A5: ☐ | B5: 46333 | C5: Sat | D5: 1 | E5: 1: DocuLens | F5: 5 | G5: 10:30-13:30 PROJECT (3 h) | H5: D04 | I5: Upload + PyMuPDF extraction with coordinates | J5: 1. POST /documents (multipart): check magic bytes %PDF-, size cap (e.g. 25 MB), page cap; compute sha256 while reading. 2. If the same sha256 already exists in the workspace, return the existing document (200) instead of creating a duplicate (idempotent upload). Document the 200 vs 409 choice. 3. Save the file under ./storage/{document_id}.pdf behind a Storage interface (LocalStorage now, Blob later). 4. extract_blocks(path) -> list[Block(page, bbox, text, font_size, is_bold)] using page.get_text('dict'); skip empty/whitespace spans. 5. Pick a corpus: 5-8 public insurance policy wordings (recommended: in week 6 your claim workflow checks claims against these same policies) or pharma drug labels, + 1 scanned PDF. Put 2 small ones in tests/fixtures/. 6. Tests: block count > 0 for the fixture; every bbox has 4 floats inside the page rect; second upload returns the same id. Stretch: Print the 10 largest-font blocks of a document: those are your heading candidates for D05. | K5: Uploading the same PDF twice returns the same document_id, and the extraction test proves every block has a page number and a valid bbox. | L5: PyMuPDF docs 'Text extraction' + 'Appendix 1: Details on Text Extraction' (page.get_text('dict')); FastAPI 'Request Files'. | O5: 14:30-15:30 BACKEND LAB: LAB00 HTTP from raw sockets. Done when: Python socket server that parses a GET request and returns a valid HTTP/1.1 response; curl works against it. 16:00-17:00 JOB HUNT: LinkedIn: headline 'AI Engineer | LLM agents, RAG | Python, FastAPI | Copilot Studio', About (5 lines), skills; open-to-work for recruiters only. 17:00-18:00 OPTIONAL: carry-over, tests, docs (never tomorrow's card) | P5: WIN = project 'Done when' met + lab 'Done when' met + job-hunt task done. | Q5: 0 | R5: ☐
A6: ☐ | B6: 46334 | C6: Sun | D6: 1 | E6: 1: DocuLens | F6: 5 | G6: 10:30-13:00 PROJECT (2.5 h) | H6: D05 | I6: Chunking strategies v1 (layout-aware) | J6: 1. Chunker A, fixed: 400 tokens, 60 overlap (tiktoken cl100k as the counter). 2. Chunker B, recursive: split on paragraph -> sentence -> word to stay under 400 tokens. 3. Chunker C, layout-aware: walk blocks in reading order; a block whose font size is above the page median (or bold + short) starts a new section; never merge across sections; keep the heading path ('3 Exclusions > 3.2 Pre-existing') in chunk.section. 4. Every chunk keeps page, union bbox of its blocks, token_count and content_hash (sha256 of normalised text). 5. scripts/chunk_stats.py prints count / mean / p95 tokens per strategy for the corpus. | K6: Unit tests pass for all three chunkers, chunk_stats prints a table for your corpus, and docs/decisions/0002-chunking.md states your provisional pick (to be confirmed by eval in D16). | L6: Pinecone 'Chunking Strategies for LLM Applications' article; LangChain RecursiveCharacterTextSplitter docs (concept only); tiktoken README. | O6: 14:00-15:00 MOCK & STORY: Write and record 'Tell me about yourself' v1 (90 s). Write 5 bullets describing your Copilot Studio work in engineering terms (integrations, APIs, data, auth, deployment/ALM). 15:00-16:00 READ / CERT: Read Anthropic's 'Building effective agents' essay; write 10 bullets in your own words. 16:00-16:30 WEEKLY REVIEW: tick the week, scorecard (project cards x/6, LARP x/4, mock score, applications x/0), 3 lines in LOG.md, read next week's first card. | P6: WIN = project 'Done when' met + story/mock recorded + weekly review written (scorecard, 3 lines, next week's first card read). | R6: ☐
A7: ☐ | B7: 46335 | C7: Mon | D7: 2 | E7: 1: DocuLens | F7: 3 | G7: 22:00-23:45 PROJECT (105 min) | H7: D06 | I7: Embeddings + dense search on pgvector (HNSW) | J7: 1. EmbeddingProvider protocol: embed_documents(list[str]) / embed_query(str). Implement FastEmbedProvider (BAAI/bge-small-en-v1.5, 384-d, runs on CPU, free) and FakeEmbedder for tests. 2. Pipeline step: embed chunks in batches of 64; store vectors. 3. Migration: HNSW index USING hnsw (embedding vector_cosine_ops). 4. POST /search {query, k, mode:'dense'} -> chunks with score, page, section, document filename. 5. Run EXPLAIN on the search query and confirm the index is used (set enable_seqscan=off only to test). Stretch: Try ef_search 40 vs 200 on 10 queries and note latency vs result changes. | K7: A natural question ('what is not covered?') returns sensible top-5 chunks with page numbers, and EXPLAIN shows the HNSW index scan. | L7: pgvector README sections 'Querying', 'HNSW', 'Filtering'; fastembed README (qdrant/fastembed); MTEB leaderboard (concept: how models are compared). | M7: 23:45-01:00 LARP (75 min) | N7: L03 Embeddings and vector search (ANN, HNSW vs IVFFlat) | P7: WIN = project 'Done when' met and pushed (or one clean carry-over line in docs/LOG.md) + LARP quiz scored, misses written as flashcards + DSA ticked (office). | R7: ☐
A8: ☐ | B8: 46336 | C8: Tue | D8: 2 | E8: 1: DocuLens | F8: 3 | G8: 22:00-23:45 PROJECT (105 min) | H8: D07 | I8: Lexical leg: Postgres full-text search | J8: 1. Migration: generated column tsv tsvector GENERATED ALWAYS AS (to_tsvector('english', coalesce(section,'') || ' ' || text)) STORED + GIN index. 2. mode='lexical': websearch_to_tsquery + ts_rank_cd ordering, same response shape as dense. 3. Find 3 queries where lexical beats dense (exact clause id, rare term, acronym) and 3 where dense beats lexical (paraphrase). Write them in docs/notes/retrieval-examples.md - these are interview examples. 4. Note honestly: ts_rank_cd is not true BM25 (no IDF saturation tuning); record that as a known limit. Stretch: Add bm25s (pip) over the same chunks and compare top-5 for your 6 example queries. | K8: docs/notes/retrieval-examples.md lists at least 3 queries where lexical finds the right chunk and dense does not, and 3 the other way round. | L8: PostgreSQL docs chapter 12 'Full Text Search' (12.1-12.3, websearch_to_tsquery, ts_rank_cd); 'BM25' explanation (Elastic blog 'Practical BM25'). | M8: 23:45-01:00 LARP (75 min) | N8: L04 BM25 and full-text search | P8: WIN = project 'Done when' met and pushed (or one clean carry-over line in docs/LOG.md) + LARP quiz scored, misses written as flashcards + DSA ticked (office). | R8: ☐
A9: ☐ | B9: 46337 | C9: Wed | D9: 2 | E9: 1: DocuLens | F9: 3 | G9: 22:00-23:45 PROJECT (105 min) | H9: D08 | I9: Hybrid retrieval with Reciprocal Rank Fusion + metadata filters | J9: 1. Run dense and lexical legs concurrently (asyncio.gather), each returning top 30. 2. rrf(lists, k=60): score = sum(1/(k + rank)). Pure function + unit test with hand-made rankings. 3. Metadata filters applied INSIDE both legs (document_ids, doc_type, page range) - pre-filtering, not post-filtering. 4. mode='hybrid' is the default; debug=true returns each chunk's dense rank, lexical rank and fused score. Stretch: Add a weight per leg (weighted RRF) behind a setting; you'll tune it with eval data in W3. | K9: RRF unit test passes, and /search?debug=true shows per-leg ranks and the fused order for any query. | L9: Paper/summary: 'Reciprocal Rank Fusion outperforms Condorcet...' (Cormack et al. 2009) - read the abstract and formula only; pgvector 'Hybrid search' section. | M9: 23:45-01:00 LARP (75 min) | N9: L05 Hybrid search, Reciprocal Rank Fusion and metadata filtering | P9: WIN = project 'Done when' met and pushed (or one clean carry-over line in docs/LOG.md) + LARP quiz scored, misses written as flashcards + DSA ticked (office). | R9: ☐
A10: ☐ | B10: 46338 | C10: Thu | D10: 2 | E10: 1: DocuLens | F10: 3 | G10: 22:00-23:45 PROJECT (105 min) | H10: D09 | I10: Reranking with a cross-encoder | J10: 1. Reranker protocol + CrossEncoderReranker (sentence-transformers, BAAI/bge-reranker-base) + NoopReranker. 2. Rerank the fused top-30 down to top-5. Model call is CPU-bound: run it with run_in_threadpool / anyio.to_thread so the event loop is not blocked. 3. Load the model once at startup (lifespan), not per request. 4. Log rerank latency; scripts/bench_rerank.py prints p50/p95 for 20 queries. 5. Setting RERANK_ENABLED to switch it off (you will compare in eval). Stretch: Try top-20 vs top-50 candidates and note the latency change. | K10: debug output shows the order before and after reranking, and bench_rerank prints p50/p95 latency for 20 queries. | L10: sbert.net 'Cross-Encoders' + 'Retrieve & Re-Rank' pages; BAAI/bge-reranker-base model card. | M10: 23:45-01:00 LARP (75 min) | N10: L06 Rerankers: bi-encoders vs cross-encoders | P10: WIN = project 'Done when' met and pushed (or one clean carry-over line in docs/LOG.md) + LARP quiz scored, misses written as flashcards + DSA ticked (office). | R10: ☐
A11: ☐ | B11: 46339 | C11: Fri | D11: 2 | E11: 1: DocuLens | F11: 3 | G11: 22:00-23:45 BUFFER + POLISH | H11: BUF | I11: Carry-over first | J11: If no carry-over: README section 'How retrieval works' + raise test coverage of app/retrieval. | K11: No open carry-over from this week (or exactly one carried line in docs/LOG.md). | M11: 23:45-01:00 WEEKLY MOCK | N11: Weekly mock interview (Friday prompt). Topics: L03 Embeddings and vector search (ANN, HNSW vs IVFFlat), L04 BM25 and full-text search, L05 Hybrid search, Reciprocal Rank Fusion and metadata filtering, L06 Rerankers: bi-encoders vs cross-encoders | P11: WIN = carry-over cleared (or the polish task done) + weekly mock scored with your 5 'rewrite' answers listed. | R11: ☐
A12: ☐ | B12: 46340 | C12: Sat | D12: 2 | E12: 1: DocuLens | F12: 5 | G12: 10:30-13:30 PROJECT (3 h) | H12: D10 | I12: LLM layer: providers, structured output, grounded answers with citations | J12: 1. LLMProvider protocol: complete(messages, model, max_tokens, temperature, response_schema=None) -> LLMResult(text|parsed, usage, latency_ms, model, provider). 2. Adapters: OpenAICompatibleProvider (works for OpenAI and Gemini via base_url) and AnthropicProvider. FakeProvider for tests. Use the cheapest current model of each. 3. generate_structured(schema): ask for JSON matching the Pydantic schema; on ValidationError re-ask once with the error message; then fail with a typed error. 4. Answer schema: {answer: str, citations: list[chunk_id], confidence: float 0-1, unanswerable: bool}. 5. POST /ask: hybrid retrieve -> rerank -> prompt with numbered chunks -> structured answer -> reject citations that are not in the retrieved set. 6. Prompt says: answer only from the context, cite chunk ids, set unanswerable=true if the context does not contain the answer. Stretch: Return the bbox of each cited chunk so a UI could highlight it on the page. | K12: /ask answers a corpus question with valid citation ids (each maps to a page), an out-of-corpus question returns unanswerable=true, and a test proves invented citation ids are rejected. | L12: OpenAI docs 'Structured Outputs'; Anthropic docs 'Tool use' (for JSON via tools) and 'Increase output consistency'; Gemini 'OpenAI compatibility' page. | O12: 14:30-15:30 BACKEND LAB: LAB01 Cache-aside + stampede. Done when: Redis cache-aside over a slow DB call; 100 concurrent misses on expiry hit the DB 100 times, then a SET NX single-flight lock + jittered TTL brings it to 1. 16:00-17:00 JOB HUNT: Resume v1 draft (1 page): Copilot Studio work in engineering terms + DocuLens 'in progress' section. Build a JD keyword list from the JD Skill Matrix sheet. 17:00-18:00 OPTIONAL: carry-over, tests, docs (never tomorrow's card) | P12: WIN = project 'Done when' met + lab 'Done when' met + job-hunt task done. | Q12: 0 | R12: ☐
A13: ☐ | B13: 46341 | C13: Sun | D13: 2 | E13: 1: DocuLens | F13: 5 | G13: 10:30-13:00 PROJECT (2.5 h) | H13: D11 | I13: Streaming answers over SSE + conversation memory | J13: 1. POST /ask/stream returns text/event-stream: event 'token' for answer tokens, then one final event 'citations' with JSON, then 'done'. 2. Implement stream() on both providers (async generator). 3. Conversation: conversations + messages tables; /ask accepts conversation_id; last 6 turns are condensed into a standalone question before retrieval (LLM 'condense' step). 4. Handle client disconnect (request.is_disconnected) so you stop paying for tokens nobody reads. 5. Test the stream with httpx streaming client; manual test with curl -N. | K13: curl -N shows tokens arriving incrementally and a final citations event; a follow-up question ('and what about dental?') is rewritten into a standalone query that retrieves the right chunks. | L13: MDN 'Using server-sent events'; FastAPI 'StreamingResponse' (or sse-starlette README); OpenAI/Anthropic streaming docs. | O13: 14:00-15:00 MOCK & STORY: Record a 3-minute DocuLens architecture walkthrough of what exists; listen back; cut filler words; re-record. 15:00-16:00 READ / CERT: Chip Huyen, 'AI Engineering' - RAG and agents chapter (first half). Notes in your own words. 16:00-16:30 WEEKLY REVIEW: tick the week, scorecard (project cards x/6, LARP x/4, mock score, applications x/0), 3 lines in LOG.md, read next week's first card. | P13: WIN = project 'Done when' met + story/mock recorded + weekly review written (scorecard, 3 lines, next week's first card read). | R13: ☐
A14: ☐ | B14: 46342 | C14: Mon | D14: 3 | E14: 1: DocuLens | F14: 3 | G14: 22:00-23:45 PROJECT (105 min) | H14: D12 | I14: Async ingestion with Celery + Redis (202 + job status) | J14: 1. celery_app.py with Redis broker/result backend; worker service in docker-compose using the same image. 2. jobs table: id, document_id, stage (queued|extracting|chunking|embedding|ready|failed), progress, error, attempts, timestamps. 3. POST /documents now stores the file, creates job, enqueues ingest_document(document_id) and returns 202 {job_id}. 4. Celery chain: extract -> chunk -> embed, each updating the job stage. 5. GET /jobs/{id} returns stage/progress/error. 6. docs/decisions/0003-celery.md: Celery vs FastAPI BackgroundTasks vs arq (why a real broker). | K14: Uploading a 50-page PDF returns 202 in under 300 ms and GET /jobs/{id} moves queued -> extracting -> chunking -> embedding -> ready. | L14: Celery 'First steps with Celery' + 'Tasks' (acks_late, retries); FastAPI 'Background Tasks' page (to explain why you did NOT use it). | M14: 23:45-01:00 LARP (75 min) | N14: L07 Task queues: Celery, Redis, delivery guarantees | P14: WIN = project 'Done when' met and pushed (or one clean carry-over line in docs/LOG.md) + LARP quiz scored, misses written as flashcards + DSA ticked (office). | R14: ☐
A15: ☐ | B15: 46343 | C15: Tue | D15: 3 | E15: 1: DocuLens | F15: 3 | G15: 22:00-23:45 PROJECT (105 min) | H15: D13 | I15: Retries, idempotent tasks and chunk-level de-duplication | J15: 1. Retries: autoretry_for transient errors (timeouts, 429, connection) with retry_backoff + jitter, max 5; permanent errors (corrupt PDF) fail fast with a clear job error. 2. Idempotency: each stage checks whether its output already exists; UNIQUE(document_id, content_hash, page) prevents duplicate chunks. 3. Exact dedup: normalised text hash. Near-dup: MinHash (datasketch) with Jaccard >= 0.9 marks repeated headers/footers/boilerplate as is_boilerplate=true and excludes them from search. 4. Kill the worker mid-embedding (docker kill), restart, verify the job completes without duplicates. | K15: Re-running ingest for the same document does not change the chunk count, the kill-worker test completes the job with no duplicates, and the job report shows how many boilerplate chunks were removed. | L15: Celery 'Retrying' + 'acks_late' notes; datasketch MinHash/LSH README; article on SimHash (optional). | M15: 23:45-01:00 LARP (75 min) | N15: L08 Idempotency and de-duplication | P15: WIN = project 'Done when' met and pushed (or one clean carry-over line in docs/LOG.md) + LARP quiz scored, misses written as flashcards + DSA ticked (office). | R15: ☐
A16: ☐ | B16: 46344 | C16: Wed | D16: 3 | E16: 1: DocuLens | F16: 3 | G16: 22:00-23:45 PROJECT (105 min) | H16: D14 | I16: Metadata extraction with structured outputs + filtered search | J16: 1. DocMetadata schema: title, doc_type (Literal of 4-5 values), issuer, product_names list, effective_date (date|None), language. 2. Celery stage 'extract_metadata': first 3 pages -> cheap model -> DocMetadata; regex fallback for dates if the model fails. 3. Store in documents.metadata and copy doc_type/issuer into chunk metadata for filtering. 4. /search and /ask accept filters {doc_type, issuer}. 5. Add a 'route by metadata' rule: if the question names an issuer/product, filter automatically (simple keyword match against known products). | K16: Every corpus document has extracted metadata you have checked by eye, and a filtered query only returns chunks from matching documents. | L16: Instructor library README (concept of retries on validation) - you already built the equivalent; Pydantic 'Field' + 'Literal' docs. | M16: 23:45-01:00 LARP (75 min) | N16: L09 Structured outputs and prompt engineering | P16: WIN = project 'Done when' met and pushed (or one clean carry-over line in docs/LOG.md) + LARP quiz scored, misses written as flashcards + DSA ticked (office). | R16: ☐
A17: ☐ | B17: 46345 | C17: Thu | D17: 3 | E17: 1: DocuLens | F17: 3 | G17: 22:00-23:45 PROJECT (105 min) | H17: D15 | I17: Golden evaluation dataset (frozen) | J17: 1. Write 30 questions over your corpus: 10 single-fact lookups, 6 exact-term/clause questions, 8 multi-hop or compare-two-documents, 6 unanswerable (not in corpus). 2. For each: reference answer (1-2 lines), expected document + page(s), type tag. 3. Store as eval/golden_v1.jsonl and a loader with Pydantic validation. 4. Freeze it: git tag eval-v1. Rule from your old plan stays: never edit labels to make a run pass. 5. Optional: generate 20 extra synthetic questions with an LLM, but keep them in a separate file and label them synthetic. | K17: eval/golden_v1.jsonl has 30 validated rows with expected pages and types, and the tag eval-v1 exists. | L17: RAGAS docs 'Testset' concepts; Hamel Husain's blog posts on evals ('Your AI product needs evals'). | M17: 23:45-01:00 LARP (75 min) | N17: L10 Evaluating RAG systems | P17: WIN = project 'Done when' met and pushed (or one clean carry-over line in docs/LOG.md) + LARP quiz scored, misses written as flashcards + DSA ticked (office). | R17: ☐
A18: ☐ | B18: 46346 | C18: Fri | D18: 3 | E18: 1: DocuLens | F18: 3 | G18: 22:00-23:45 BUFFER + POLISH | H18: BUF | I18: Carry-over first | J18: If no carry-over: polish resume v1, tidy docs/decisions. | K18: No open carry-over from this week (or exactly one carried line in docs/LOG.md). | M18: 23:45-01:00 WEEKLY MOCK | N18: Weekly mock interview (Friday prompt). Topics: L07 Task queues: Celery, Redis, delivery guarantees, L08 Idempotency and de-duplication, L09 Structured outputs and prompt engineering, L10 Evaluating RAG systems | P18: WIN = carry-over cleared (or the polish task done) + weekly mock scored with your 5 'rewrite' answers listed. | R18: ☐
A19: ☐ | B19: 46347 | C19: Sat | D19: 3 | E19: 1: DocuLens | F19: 5 | G19: 10:30-13:30 PROJECT (3 h) | H19: D16 | I19: Retrieval evaluation harness: numbers for your design choices | J19: 1. eval/retrieval.py: for each golden question run a retrieval config, mark a hit when an expected page/chunk is in top-k. 2. Metrics: recall@5, recall@10, MRR, and context precision (fraction of retrieved chunks that are relevant, using page match). 3. Configs: dense / lexical / hybrid / hybrid+rerank x chunkers A/B/C (at least 6 runs). 4. Write docs/eval/retrieval_v1.md: table + 3-sentence conclusion + chosen default. Update decision 0002-chunking.md with the evidence. 5. Exclude unanswerable questions from recall, but report them separately. | K19: docs/eval/retrieval_v1.md has a table of at least 6 configs x 3 metrics and you can state, from memory, which config won and by how much. | L19: Recall@k, MRR, nDCG definitions (any IR textbook or Pinecone 'Evaluation Measures in IR'). | O19: 14:30-15:30 BACKEND LAB: LAB02 Rate limiters. Done when: Fixed window vs token bucket (Lua) in Redis; a burst test shows the fixed-window edge problem and the bucket's smooth behaviour. 16:00-17:00 JOB HUNT: Target list: 40 companies (product/SaaS, AI startups, GCCs) + 10 recruiters in the Job Tracker; job alerts on LinkedIn, Naukri, Instahyre, Wellfound. Resume v1 final. GATE 0 on Sunday: send the first 3 applications. 17:00-18:00 OPTIONAL: carry-over, tests, docs (never tomorrow's card) | P19: WIN = project 'Done when' met + lab 'Done when' met + job-hunt task done. | Q19: 3 | R19: ☐
A20: ☐ | B20: 46348 | C20: Sun | D20: 3 | E20: 1: DocuLens | F20: 5 | G20: 10:30-13:00 PROJECT (2.5 h) | H20: D17 | I20: Generation eval (RAGAS or DeepEval) + Langfuse tracing | J20: 1. Instrument /ask with Langfuse: one trace per request, spans for condense, retrieve, rerank, generate; record model, tokens, cost, prompt version. 2. eval/generation.py: run the golden set through /ask, score faithfulness, answer relevancy, context precision/recall with RAGAS (or DeepEval); also exact checks: unanswerable questions must return unanswerable=true. 3. Push scores to Langfuse as scores on each trace. 4. docs/eval/generation_v1.md: table + 3 worst answers with a one-line diagnosis each (retrieval miss vs generation error). Stretch: Use a different (cheaper) judge model than the answer model and note why. | K20: One full eval run is visible in Langfuse with per-trace scores, and generation_v1.md lists metrics plus the 3 worst failures with a diagnosis. | L20: Langfuse docs 'Get started' (self-host with docker compose or free cloud) + Python decorator @observe; RAGAS metrics page (faithfulness, answer_relevancy, context_precision, context_recall) or DeepEval 'Getting started'. | O20: 14:00-15:00 MOCK & STORY: STAR stories 1-2 from your real job (a hard integration; a production issue you fixed). Write in the Story Bank, then say them aloud. 15:00-16:00 READ / CERT: Chip Huyen, 'AI Engineering' - evaluation chapters (skim). Note 5 ideas you will use. 16:00-16:30 WEEKLY REVIEW: tick the week, scorecard (project cards x/6, LARP x/4, mock score, applications x/3), 3 lines in LOG.md, read next week's first card. | P20: WIN = project 'Done when' met + story/mock recorded + weekly review written (scorecard, 3 lines, next week's first card read). | R20: ☐ | S20: Gate 0: Resume v1, LinkedIn, GitHub ready (DocuLens with hybrid search and first eval table). First 3 applications; 8/week next week. Interviews are practice and market information.
A21: ☐ | B21: 46349 | C21: Mon | D21: 4 | E21: 1: DocuLens | F21: 3 | G21: 22:00-23:45 PROJECT (105 min) | H21: D18 | I21: Model router: capability routing, fallback, usage ledger | J21: 1. models.yaml: capabilities (extract_metadata, condense, answer, judge) -> ordered list of provider/model with max_tokens and timeout. 2. Router.complete(capability, ...): try primary; on timeout/429/5xx retry once with jittered backoff, then fall back to the next provider. Never fall back on a schema-validation failure that survived the re-ask (that is a prompt bug, not an outage). 3. usage_ledger table: request_id, capability, provider, model, input/output tokens, cost estimate, latency, status (ok|retried|fallback|failed). 4. GET /usage?from&to aggregates cost and calls per capability/model. 5. Test: FakeProvider that returns 429 forces a fallback; ledger shows both attempts. Stretch: Add a simple circuit breaker per provider (open after 5 failures in 60 s). | K21: The forced-429 test shows primary -> fallback in the ledger, and GET /usage returns cost per capability for your eval run. | L21: Your own LLM layer from D10; AWS Builders Library 'Timeouts, retries and backoff with jitter' (read it - it is also a backend interview classic). | M21: 23:45-01:00 LARP (75 min) | N21: L11 LLM routing, fallback, retries, timeouts, circuit breakers | P21: WIN = project 'Done when' met and pushed (or one clean carry-over line in docs/LOG.md) + LARP quiz scored, misses written as flashcards + DSA ticked (office). | R21: ☐
A22: ☐ | B22: 46350 | C22: Tue | D22: 4 | E22: 1: DocuLens | F22: 3 | G22: 22:00-23:45 PROJECT (105 min) | H22: D19 | I22: Query transformation: rewrite, multi-query, HyDE | J22: 1. Multi-query: LLM writes 3 paraphrases; retrieve for each; fuse with RRF. 2. HyDE: LLM writes a hypothetical answer; embed it for the dense leg only. 3. Decomposition for compare questions: split 'A vs B' into two sub-queries. 4. Feature flags per technique; run the retrieval eval on golden_v1 for each. 5. Add rows to retrieval_v1.md and record keep/drop decisions with the cost (extra LLM calls, latency). | K22: The retrieval table has rows for multi-query and HyDE with recall@5 and added latency, and each has a written keep/drop decision. | L22: LangChain 'MultiQueryRetriever' concept page; HyDE paper abstract (Gao et al. 2022); 'step-back prompting' summary. | M22: 23:45-01:00 LARP (75 min) | N22: L12 Chunking strategies and query transformation | P22: WIN = project 'Done when' met and pushed (or one clean carry-over line in docs/LOG.md) + LARP quiz scored, misses written as flashcards + DSA ticked (office). | R22: ☐
A23: ☐ | B23: 46351 | C23: Wed | D23: 4 | E23: 1: DocuLens | F23: 3 | G23: 22:00-23:45 PROJECT (105 min) | H23: D20 | I23: LangGraph 1: your RAG pipeline as a StateGraph | J23: 1. RAGState TypedDict: question, conversation_id, filters, standalone_question, candidates, context, answer, citations, confidence, steps (Annotated list with operator.add reducer). 2. Nodes: condense -> retrieve -> rerank -> generate. Each node is a small pure-ish function calling your existing services. 3. Compile; expose POST /agent/ask that invokes the graph. 4. Export the Mermaid diagram (graph.get_graph().draw_mermaid()) into README. 5. Unit test the graph with FakeProvider and FakeEmbedder. | K23: /agent/ask returns the same quality answer as /ask (spot check 5 golden questions), and the Mermaid diagram is in the README. | L23: LangGraph docs (docs.langchain.com, LangGraph section): 'Quickstart', 'Graph API' (state, reducers, nodes, edges). | M23: 23:45-01:00 LARP (75 min) | N23: L13 LangGraph core: state, nodes, edges, reducers, checkpointers | P23: WIN = project 'Done when' met and pushed (or one clean carry-over line in docs/LOG.md) + LARP quiz scored, misses written as flashcards + DSA ticked (office). | R23: ☐
A24: ☐ | B24: 46352 | C24: Thu | D24: 4 | E24: 1: DocuLens | F24: 3 | G24: 22:00-23:45 PROJECT (105 min) | H24: D21 | I24: LangGraph 2: conditional routing + self-correction (corrective RAG) | J24: 1. route_question node (structured output): direct (chit-chat/meta), retrieve, or clarify (ambiguous). 2. grade_documents node: cheap model labels each chunk relevant/irrelevant in ONE batched call. 3. If no relevant chunks: rewrite_query -> retrieve again, max 2 loops (loop counter in state). 4. check_grounding node after generate: if the answer is not supported by the cited chunks -> regenerate once, else abstain with unanswerable=true. 5. Tests with FakeProvider scripted responses covering: direct, retrieve-ok, rewrite-loop-hits-cap, abstain. | K24: Four graph tests (direct, normal retrieve, rewrite loop capped at 2, abstain) pass, and the golden unanswerable questions now abstain at least 5 of 6 times. | L24: LangGraph tutorial 'Agentic RAG' / 'Adaptive RAG' pages; Self-RAG and CRAG paper abstracts. | M24: 23:45-01:00 LARP (75 min) | N24: L14 Agentic patterns: ReAct, tool calling, HITL, self-correction, multi-agent | P24: WIN = project 'Done when' met and pushed (or one clean carry-over line in docs/LOG.md) + LARP quiz scored, misses written as flashcards + DSA ticked (office). | R24: ☐
A25: ☐ | B25: 46353 | C25: Fri | D25: 4 | E25: 1: DocuLens | F25: 3 | G25: 22:00-23:45 BUFFER + POLISH | H25: BUF | I25: Carry-over first | J25: If no carry-over: graph tests, zero mypy errors. Plus 30 min applications. | K25: No open carry-over from this week (or exactly one carried line in docs/LOG.md). | M25: 23:45-01:00 WEEKLY MOCK | N25: Weekly mock interview (Friday prompt). Topics: L11 LLM routing, fallback, retries, timeouts, circuit breakers, L12 Chunking strategies and query transformation, L13 LangGraph core: state, nodes, edges, reducers, checkpointers, L14 Agentic patterns: ReAct, tool calling, HITL, self-correction, multi-agent | P25: WIN = carry-over cleared (or the polish task done) + weekly mock scored with your 5 'rewrite' answers listed. | R25: ☐
A26: ☐ | B26: 46354 | C26: Sat | D26: 4 | E26: 1: DocuLens | F26: 5 | G26: 10:30-13:30 PROJECT (3 h) | H26: D22 | I26: LangGraph 3: tools, human-in-the-loop interrupt, Postgres checkpointer | J26: 1. Tools (typed, read-only): search_documents(query, filters), get_page_text(document_id, page), list_documents(doc_type). Bind to the answer model; ToolNode executes them. 2. PostgresSaver checkpointer; every request carries thread_id = conversation_id. 3. interrupt() before returning when confidence < 0.6 OR the question asks for a decision (e.g. 'is my claim covered?'): the state is saved and the API returns status=needs_review with the draft. 4. POST /agent/threads/{id}/resume {decision: approve|edit|reject, edited_answer?} resumes with Command(resume=...). 5. Test: pause, restart the API container, resume - the thread continues from the checkpoint. | K26: A low-confidence question pauses with needs_review, survives an API restart, and completes after POST /resume. | L26: LangGraph docs: 'Tools'/'ToolNode', 'Persistence' (checkpointers, thread_id), 'Human-in-the-loop' (interrupt, Command(resume=...)); langgraph-checkpoint-postgres README. | O26: 14:30-15:30 BACKEND LAB: LAB03 Idempotency keys. Done when: POST /payments with Idempotency-Key: concurrent duplicates execute once; retry returns the stored response. 16:00-17:00 JOB HUNT: 8 applications + 3 referral messages. Log every interview question you get in the Interview Log. 17:00-18:00 OPTIONAL: carry-over, tests, docs (never tomorrow's card) | P26: WIN = project 'Done when' met + lab 'Done when' met + job-hunt task done. | Q26: 8 | R26: ☐
A27: ☐ | B27: 46355 | C27: Sun | D27: 4 | E27: 1: DocuLens | F27: 5 | G27: 10:30-13:00 PROJECT (2.5 h) | H27: D23 | I27: Multi-document comparison: fan-out with Send (map-reduce) | J27: 1. Route compare-type questions to a compare branch. 2. planner node: identify target documents (from metadata) and the aspect to compare. 3. Send one task per document to a per_document subgraph (retrieve within that document -> extract structured findings with citations). 4. aggregate node: builds a comparison table (aspect x document) with citations; abstain per cell if nothing found. 5. Cap fan-out at 5 documents; per-branch timeout; a failed branch shows 'not found' instead of failing the whole answer. Stretch: Deep-research report mode: a planner writes 3-5 sub-questions, Send fans them out, a writer composes a cited report and a checker deletes unsupported sentences. Keep it only if 3 sample reports pass your grounding check. | K27: 'Compare exclusions in policy A vs policy B' returns a table with citations from both documents, and the Langfuse trace shows the parallel branches. | L27: LangGraph docs 'Map-reduce with Send API' and 'Subgraphs'; your backend patterns notes on fan-out/fan-in. | O27: 14:00-15:00 MOCK & STORY: Design-choice defence: answer the DocuLens questions in the Design Choices sheet aloud (record, score yourself). 15:00-16:00 READ / CERT: LangGraph docs: low-level concepts (state, reducers, persistence, interrupts) end to end. 16:00-16:30 WEEKLY REVIEW: tick the week, scorecard (project cards x/6, LARP x/4, mock score, applications x/8), 3 lines in LOG.md, read next week's first card. | P27: WIN = project 'Done when' met + story/mock recorded + weekly review written (scorecard, 3 lines, next week's first card read). | R27: ☐
A28: ☐ | B28: 46356 | C28: Mon | D28: 5 | E28: 1: DocuLens | F28: 3 | G28: 22:00-23:45 PROJECT (105 min) | H28: D24 | I28: Auth, workspaces and RBAC (tenant isolation) | J28: 1. users, workspaces, memberships(role: owner|editor|viewer); signup/login returning access (15 min) + refresh (7 days, stored hashed, rotated) tokens. 2. get_current_principal dependency -> (user_id, workspace_id, role). 3. Every query on documents/chunks/jobs/threads filters by workspace_id - put it in the repository layer so it cannot be forgotten. 4. Viewer cannot upload or delete; editor can; owner manages members. 5. Isolation tests: user B cannot see A's documents via /documents, /search, /ask, /agent tools, or by guessing a document id (404, not 403). | K28: The two-user isolation test suite passes for every endpoint, including the agent's tools. | L28: FastAPI 'Security - OAuth2 with Password, Bearer with JWT'; OWASP 'Authorization Cheat Sheet' (skim); pwdlib/argon2 README. | M28: 23:45-01:00 LARP (75 min) | N28: L15 Authentication, authorization, JWT, OAuth2/OIDC, RBAC, multi-tenancy | P28: WIN = project 'Done when' met and pushed (or one clean carry-over line in docs/LOG.md) + LARP quiz scored, misses written as flashcards + DSA ticked (office). | R28: ☐
A29: ☐ | B29: 46357 | C29: Tue | D29: 5 | E29: 1: DocuLens | F29: 3 | G29: 22:00-23:45 PROJECT (105 min) | H29: D25 | I29: Production Dockerfiles + GitHub Actions CI | J29: 1. Multi-stage Dockerfile: builder installs deps with uv into .venv, runtime copies it; non-root user; HEALTHCHECK; pre-download the embedding/reranker models at build time. 2. Same image runs api (uvicorn) and worker (celery) with different commands. 3. CI workflow: ruff, mypy, pytest with postgres(pgvector)+redis service containers, docker build, and an eval smoke test (5 golden questions with FakeProvider asserting the pipeline wiring). 4. Cache uv and Docker layers in CI. 5. README badge. | K29: CI is green on a pull request, the runtime image runs as non-root, and an intentionally broken test makes CI fail. | L29: Docker docs 'Multi-stage builds'; uv docs 'Using uv in Docker'; GitHub Actions 'Creating PostgreSQL service containers'. | M29: 23:45-01:00 LARP (75 min) | N29: L16 Docker in depth + CI/CD with GitHub Actions | P29: WIN = project 'Done when' met and pushed (or one clean carry-over line in docs/LOG.md) + LARP quiz scored, misses written as flashcards + DSA ticked (office). | R29: ☐
A30: ☐ | B30: 46358 | C30: Wed | D30: 5 | E30: 1: DocuLens | F30: 3 | G30: 22:00-23:45 PROJECT (105 min) | H30: D26 | I30: Azure foundation (budget first) | J30: 1. Budget + alert at a small monthly cap before creating anything. One region (e.g. Central India). Tag every resource project=doculens. 2. infra/azure/setup.sh using az CLI: resource group, Azure Container Registry, Log Analytics workspace + Container Apps environment, PostgreSQL Flexible Server (Burstable B1ms) with azure.extensions=VECTOR, Storage account + private container, Key Vault. 3. Enable vector extension and run Alembic migrations against Azure PG from your laptop (firewall rule for your IP only). 4. BlobStorage implementation of your Storage interface (SAS URLs for download). 5. docs/cloud-cost.md: every billable resource, its expected monthly cost, and how to stop it. Stretch: teardown.sh that deletes the resource group. | K30: setup.sh recreates the environment from scratch, migrations run on Azure PG with pgvector, and a budget alert exists. | L30: Microsoft Learn: 'Azure Container Apps overview', 'Azure Database for PostgreSQL flexible server - enable pgvector', 'Key Vault basics', 'Cost Management budgets'. Check whether your employer gives a Visual Studio subscription with monthly Azure credit. | M30: 23:45-01:00 LARP (75 min) | N30: L17 Cloud fundamentals: Azure services and their AWS equivalents | P30: WIN = project 'Done when' met and pushed (or one clean carry-over line in docs/LOG.md) + LARP quiz scored, misses written as flashcards + DSA ticked (office). | R30: ☐
A31: ☐ | B31: 46359 | C31: Thu | D31: 5 | E31: 1: DocuLens | F31: 3 | G31: 22:00-23:45 PROJECT (105 min) | H31: D27 | I31: Deploy API + worker to Azure Container Apps | J31: 1. Push image to ACR (az acr build or from CI). 2. Container App 'api' (external ingress, min replicas 0-1) and 'worker' (no ingress); Redis as an internal Container App (redis:7) for v1 - write down why not Azure Cache yet (cost). 3. User-assigned managed identity: pull from ACR, read Key Vault secrets, read/write Blob. No secrets in env files or images. 4. Container Apps job for alembic upgrade head. 5. Smoke test script: health, signup, upload, poll job, ask. | K31: A public HTTPS URL passes the smoke test end to end (upload -> ready -> cited answer) and no secret value appears in the Container App configuration. | L31: Microsoft Learn: 'Deploy to Container Apps from ACR', 'Managed identities in Container Apps', 'Container Apps jobs' (for migrations). | M31: 23:45-01:00 LARP (75 min) | N31: L18 Observability: logs, metrics, traces, OpenTelemetry, LLM tracing | P31: WIN = project 'Done when' met and pushed (or one clean carry-over line in docs/LOG.md) + LARP quiz scored, misses written as flashcards + DSA ticked (office). | R31: ☐
A32: ☐ | B32: 46360 | C32: Fri | D32: 5 | E32: 1: DocuLens | F32: 3 | G32: 22:00-23:45 BUFFER + POLISH | H32: BUF | I32: Carry-over first | J32: If no carry-over: clean infra scripts, check cloud costs. Plus 30 min applications. | K32: No open carry-over from this week (or exactly one carried line in docs/LOG.md). | M32: 23:45-01:00 WEEKLY MOCK | N32: Weekly mock interview (Friday prompt). Topics: L15 Authentication, authorization, JWT, OAuth2/OIDC, RBAC, multi-tenancy, L16 Docker in depth + CI/CD with GitHub Actions, L17 Cloud fundamentals: Azure services and their AWS equivalents, L18 Observability: logs, metrics, traces, OpenTelemetry, LLM tracing | P32: WIN = carry-over cleared (or the polish task done) + weekly mock scored with your 5 'rewrite' answers listed. | R32: ☐
A33: ☐ | B33: 46361 | C33: Sat | D33: 5 | E33: 1: DocuLens | F33: 5 | G33: 10:30-13:30 PROJECT (3 h) | H33: D28 | I33: Observability, rate limiting and a load test | J33: 1. Structured JSON logs with request_id, user/workspace id, route, status, duration; propagate request_id into Celery tasks. 2. OpenTelemetry traces + metrics to Application Insights (HTTP + DB + Redis + Celery); Langfuse stays for LLM traces. 3. Per-workspace rate limit on /ask (Redis token bucket, Lua for atomicity) returning 429 + Retry-After. 4. Load test /search with 20 virtual users for 3 minutes; record p50/p95/error rate; find one bottleneck (e.g. reranker on CPU, pool size) and fix or document it. 5. docs/perf.md with before/after numbers. | K33: docs/perf.md shows p50/p95 for /search under load, one bottleneck you found, and a 429 appears when you exceed the rate limit. | L33: OpenTelemetry Python 'Getting started' + Azure Monitor OpenTelemetry distro; k6 or Locust quickstart; Redis 'rate limiting' patterns (token bucket with Lua). | O33: 14:30-15:30 BACKEND LAB: LAB04 Offset vs cursor pagination. Done when: 1M-row table; EXPLAIN ANALYZE shows page 5,000 offset vs keyset timings; numbers saved. 16:00-17:00 JOB HUNT: 10 applications + 5 referral asks. Resume v2 with the deployed link and eval numbers (GATE 1). 17:00-18:00 OPTIONAL: carry-over, tests, docs (never tomorrow's card) | P33: WIN = project 'Done when' met + lab 'Done when' met + job-hunt task done. | Q33: 10 | R33: ☐
A34: ☐ | B34: 46362 | C34: Sun | D34: 5 | E34: 1: DocuLens | F34: 5 | G34: 10:30-13:00 PROJECT (2.5 h) | H34: D29 | I34: Release v1: README, design doc, demo, resume bullets | J34: 1. README: one-paragraph pitch, architecture diagram (API, worker, Postgres+pgvector, Redis, Blob, LLM router, Langfuse), features, eval tables, 'Design decisions' links, how to run, known limits. 2. docs/design.md: 1-2 pages: problem, architecture, data flow of ingest and ask, trade-offs, what you would do at 100x scale. 3. Record a 3-minute demo video (upload -> job progress -> cited answer with page -> compare question -> needs_review pause -> resume). 4. Tag v1.0. Write 3 resume bullets using only numbers you measured (recall@5, faithfulness, p95, docs ingested). 5. Fill the 'Design Choices' sheet answers for DocuLens. | K34: v1.0 is tagged, README + design.md + demo video are linked, and the resume has 3 DocuLens bullets with real numbers. | L34: Look at 2-3 well-known open-source RAG repos' READMEs for structure; Excalidraw for the diagram. | O34: 14:00-15:00 MOCK & STORY: Full mock with Claude: 30-minute DocuLens deep dive as a senior interviewer (use the Friday mock prompt, longer). 15:00-16:00 READ / CERT: Microsoft Learn: Azure Container Apps + managed identity modules (before D26/D27 if possible). 16:00-16:30 WEEKLY REVIEW: tick the week, scorecard (project cards x/6, LARP x/4, mock score, applications x/10), 3 lines in LOG.md, read next week's first card. | P34: WIN = project 'Done when' met + story/mock recorded + weekly review written (scorecard, 3 lines, next week's first card read). | R34: ☐ | S34: Gate 1: DocuLens v1 deployed on Azure with eval report and demo. Resume v2. 10-15 applications/week + 5 referral asks.
A35: ☐ | B35: 46363 | C35: Mon | D35: 6 | E35: 1: DocuLens | F35: 3 | G35: 22:00-23:45 PROJECT (105 min) | H35: D31 | I35: Intake: document classification + per-type extraction with field confidence | J35: 1. Domain (recommended): insurance claims. Document types claim_form, hospital_bill, discharge_summary, other. One Pydantic schema per type (claimant, policy_number, incident_date, diagnosis, line_items[{description, amount}], total, hospital, ...). 2. scripts/make_claims.py: generate 30 synthetic claim packets (one PDF per document, via PyMuPDF insert_textbox or reportlab) with Faker data and a ground-truth JSON next to each. Render 5 of them as images (scanned) to exercise OCR. Plant errors on purpose: total != sum of line items, missing policy number, incident date before policy start. These are your eval labels, for free. 3. classify(document) -> doc_type + confidence: cheap model, structured output, first 2 pages only. 4. extract(document, doc_type) -> each field with value, confidence and source (page, bbox) taken from your D04 blocks. A value that does not appear on the page is marked unverified. 5. validate: Pydantic types + business rules (line items sum to total, dates in range, policy number format). Rule failures are recorded, not raised. 6. Table extractions(document_id, doc_type, schema_version, fields jsonb, field_confidence jsonb, rule_failures jsonb, model, prompt_version) + POST /documents/{id}/extract. Test on 10 packets: print classification accuracy and field exact-match accuracy. Stretch: Azure Document Intelligence prebuilt-invoice adapter for hospital bills behind the same interface; compare accuracy and cost with the LLM extractor. | K35: On 10 synthetic claim packets a script prints classification accuracy and field accuracy, and every planted error (bad total, missing policy number, bad date) is caught as a rule failure. | L35: Pydantic 'JSON Schema' page (model_json_schema); structured outputs docs of OpenAI and Anthropic; Azure AI Document Intelligence 'prebuilt invoice' overview (concept only, it is AI-102 material); Faker README. | M35: 23:45-01:00 LARP (75 min) | N35: L71 Intelligent document processing: classify, extract, validate, route | P35: WIN = project 'Done when' met and pushed (or one clean carry-over line in docs/LOG.md) + LARP quiz scored, misses written as flashcards + DSA ticked (office). | R35: ☐
A36: ☐ | B36: 46364 | C36: Tue | D36: 6 | E36: 1: DocuLens | F36: 3 | G36: 22:00-23:45 PROJECT (105 min) | H36: D32 | I36: Workflow engine: definitions, runs and durable steps | J36: 1. workflows(name, version, definition): YAML with a trigger and steps[] (type, config, on_failure, timeout). Seed claim_intake v1: classify -> extract -> validate -> policy_check -> route -> act. 2. workflow_runs(id, workflow, version, document_ids, status pending|running|waiting_review|succeeded|failed|cancelled, current_step, idempotency_key UNIQUE, started_at, ended_at) and step_runs(run_id, step, attempt, status, output jsonb, error, duration_ms). 3. Executor: build a LangGraph StateGraph from the definition (one node per step) with the Postgres checkpointer (thread_id = run_id). It runs inside a Celery task and every node writes its step_runs row. 4. Triggers: (a) upload with ?workflow=claim_intake, (b) POST /triggers/email with a simulated inbound email (JSON + attachments), (c) a Celery beat 'daily_digest' workflow. Each trigger computes an idempotency key (email message-id, or sha256 + workflow). 5. Retry policy per step: transient errors (timeout, 429, 5xx) retry with backoff + jitter; permanent errors (validation, 4xx) fail the run with the error stored. 6. Crash test: kill the worker mid-run; the restarted worker resumes from the last checkpoint and no completed step runs again. Stretch: GET /runs/{id}/timeline returning step durations - you will show it in the demo. | K36: A packet uploaded with workflow=claim_intake produces a run with one step_runs row per step, the same email trigger sent twice creates exactly one run, and a run killed mid-way resumes and finishes. | L36: LangGraph docs 'Durable execution' and 'Persistence'; Temporal 'What is durable execution?' (to compare, not to use); Celery 'Periodic tasks' (beat). | M36: 23:45-01:00 LARP (75 min) | N36: L72 Durable workflows and orchestration engines (LangGraph, Celery, Temporal, Step Functions) | P36: WIN = project 'Done when' met and pushed (or one clean carry-over line in docs/LOG.md) + LARP quiz scored, misses written as flashcards + DSA ticked (office). | R36: ☐
A37: ☐ | B37: 46365 | C37: Wed | D37: 6 | E37: 1: DocuLens | F37: 3 | G37: 22:00-23:45 PROJECT (105 min) | H37: D33 | I37: Decision step: policy-grounded coverage check + human review queue with SLAs | J37: 1. policy_check node: retrieve from the claimant's policy wording (metadata filter policy_number -> document) with your hybrid + rerank retriever; structured output {decision: covered|not_covered|unclear, clause_ids, reasons, confidence}; reuse the D10 citation validator. 2. route node is pure code, not an LLM: auto_approve only if every field is verified, there are no rule failures, decision=covered with valid citations and the amount is under a threshold; otherwise needs_review with reason codes. not_covered becomes reject_draft, which still needs a human. 3. Review queue: interrupt() -> run status waiting_review. GET /reviews (filter by reason and age); POST /reviews/{run_id} {approve | edit fields | reject, note}. Edits are stored as corrections - future eval data. 4. SLA: a Celery beat job finds reviews older than N hours, escalates them to the owner role and sends a notification; reviewer and decision go to audit_log. 5. Tests: one packet per route (auto-approve, review for low confidence, review for rule failure, reject draft) and an escalation test with a frozen clock. | K37: Four synthetic packets end in the four expected routes with reason codes, a reviewer's edit resumes the run to completion, and an overdue review is escalated by the scheduler. | L37: Your D21/D22 code (grounding check, interrupt/resume); LangGraph 'Human-in-the-loop' patterns (approve / edit / reject); a short read on straight-through processing (STP) in insurance claims. | M37: 23:45-01:00 LARP (75 min) | N37: L74 Integrations and side effects: webhooks, outbox, retries, audit | P37: WIN = project 'Done when' met and pushed (or one clean carry-over line in docs/LOG.md) + LARP quiz scored, misses written as flashcards + DSA ticked (office). | R37: ☐
A38: ☐ | B38: 46366 | C38: Thu | D38: 6 | E38: 1: DocuLens | F38: 3 | G38: 22:00-23:45 PROJECT (105 min) | H38: D34 | I38: Analytics agent: text-to-SQL over workflow data with guardrails | J38: 1. Read-only role analytics_ro with SELECT on 3-4 curated views only (v_claims, v_runs, v_reviews) and row-level security on workspace_id (SET app.workspace_id per session). 2. Schema context: YAML with view/column descriptions + 3 example question -> SQL pairs. Schema linking: embed the descriptions and give the model only the views/columns relevant to the question. 3. LangGraph: generate_sql (structured output) -> validate with sqlglot (exactly one SELECT, allow-listed views only, no dangerous functions such as pg_sleep, LIMIT 200 added) -> execute with statement_timeout 3 s -> on error feed the error back, max 2 retries -> answer in words with the SQL shown. 4. POST /analytics/ask, plus a tool query_workflow_data for the DocuLens agent: the agent now chooses between searching documents and querying data. 5. Eval: 25 questions with expected result sets (e.g. 'claims waiting for review more than 24 h, by reason'); metric = execution accuracy. Plus 5 malicious prompts ('drop table claims', 'show workspace B') that must be blocked. | K38: docs/eval/text_to_sql_v1.md records execution accuracy on 25 questions, and all 5 malicious prompts are blocked by validation or database permissions - not by the prompt. | L38: sqlglot README (parse, validate); PostgreSQL docs 'Row Security Policies' and 'GRANT'; the idea of execution accuracy from the Spider / BIRD text-to-SQL benchmarks (abstracts only). | M38: 23:45-01:00 LARP (75 min) | N38: L73 Text-to-SQL agents and safe data access | P38: WIN = project 'Done when' met and pushed (or one clean carry-over line in docs/LOG.md) + LARP quiz scored, misses written as flashcards + DSA ticked (office). | R38: ☐
